#VRML_SIM R2023a utf8

EXTERNPROTO "https://raw.githubusercontent.com/cyberbotics/webots/R2023a/projects/objects/backgrounds/protos/TexturedBackground.proto"
EXTERNPROTO "https://raw.githubusercontent.com/cyberbotics/webots/R2023a/projects/objects/backgrounds/protos/TexturedBackgroundLight.proto"
EXTERNPROTO "https://raw.githubusercontent.com/cyberbotics/webots/R2023a/projects/objects/floors/protos/RectangleArena.proto"

WorldInfo {
}
Viewpoint {
  orientation 0.1890378136187342 -0.022799874526835896 -0.9817050833849286 2.5886613931540987
  position 5.463287457077564 4.609195662189666 3.3914722225957297
}
TexturedBackground {
}
TexturedBackgroundLight {
}
DEF Arena RectangleArena {
  translation 0.0504381 0.131222 -0.0689288
  rotation 0 0 -1 0.019635
  floorSize 4 4
}
Robot {
  translation 0 0.16 0.219298
  rotation 0 1 0 0
  children [
    HingeJoint {
      jointParameters HingeJointParameters {
        anchor 0 0 0.025
      }
      device [
        RotationalMotor {
          name "finger_1"
        }
      ]
      endPoint Solid {
        translation 0.649 0 0.10499999999999998
        rotation 1 0 0 0
        children [
          Transform {
            translation 0.07 0.4 -0.048
            rotation 0 0 1 1.5708
            scale 0.01 0.01 0.01
            children [
              Shape {
                appearance PBRAppearance {
                }
                geometry Mesh {
                  url [
                    "../Downloads/curved_singular_phalange_v1.stl"
                  ]
                }
              }
            ]
          }
        ]
        name "solid(3)"
      }
    }
    HingeJoint {
      jointParameters HingeJointParameters {
        anchor 0 0 0.025
      }
      device [
        RotationalMotor {
          name "finger_2"
        }
      ]
      endPoint Solid {
        translation 0.448 0 0.10499999999999998
        rotation 1 0 0 5.307156870259904e-06
        children [
          Transform {
            translation 0.07 0.4 -0.048
            rotation 0 0 1 1.5708
            scale 0.01 0.01 0.01
            children [
              Shape {
                appearance PBRAppearance {
                }
                geometry Mesh {
                  url [
                    "../Downloads/curved_singular_phalange_v1.stl"
                  ]
                }
              }
            ]
          }
        ]
        name "solid(2)"
      }
    }
    HingeJoint {
      jointParameters HingeJointParameters {
        anchor 0 0 0.025
      }
      device [
        RotationalMotor {
          name "finger_3"
        }
      ]
      endPoint Solid {
        translation 0.22 0 0.10499999999999998
        rotation 1 0 0 5.307156870259904e-06
        children [
          Transform {
            translation 0.07 0.4 -0.048
            rotation 0 0 1 1.5708
            scale 0.01 0.01 0.01
            children [
              Shape {
                appearance PBRAppearance {
                }
                geometry Mesh {
                  url [
                    "../Downloads/curved_singular_phalange_v1.stl"
                  ]
                }
              }
            ]
          }
        ]
        name "solid(1)"
      }
    }
    HingeJoint {
      jointParameters HingeJointParameters {
        anchor 0 0 0.025
      }
      device [
        RotationalMotor {
          name "finger_4"
        }
      ]
      endPoint Solid {
        translation 0 0 0.10499999999999998
        rotation 1 0 0 0
        children [
          Transform {
            translation 0.07 0.4 -0.048
            rotation 0 0 1 1.5708
            scale 0.01 0.01 0.01
            children [
              Shape {
                appearance PBRAppearance {
                }
                geometry Mesh {
                  url [
                    "../Downloads/curved_singular_phalange_v1.stl"
                  ]
                }
              }
            ]
          }
        ]
      }
    }
    Transform {
      translation 0 -0.85 0
      rotation 0 1 0 0
      scale 0.01 0.01 0.01
      children [
        DEF Palm Shape {
          appearance PBRAppearance {
            roughness 1
          }
          geometry Mesh {
            url [
              "../Downloads/Base.stl"
            ]
            name "Palm"
          }
        }
      ]
    }
  ]
  boundingObject USE Palm
  controller "finger_controller"
}
